<?xml version="1.0" encoding="utf-8"?>
<!-- =================================================================================== -->
<!-- |    This document was autogenerated by xacro from cobotta.urdf.xacro             | -->
<!-- |    EDITING THIS FILE BY HAND IS NOT RECOMMENDED                                 | -->
<!-- =================================================================================== -->
<robot name="cobotta">
  <!-- plugin for Gazebo -->
  <gazebo>
    <plugin filename="libgazebo_ros_control.so" name="gazebo_ros_control">
      <robotNamespace>/cobotta</robotNamespace>
      <robotSimType>gazebo_ros_control/DefaultRobotHWSim</robotSimType>
      <legacyModeNS>true</legacyModeNS>
    </plugin>
  </gazebo>
  <link name="world"/>
  <joint name="joint_w" type="fixed">
    <parent link="world"/>
    <child link="base_link"/>
  </joint>
  <link name="base_link">
    <visual>
      <origin rpy="0 0 0" xyz="0 0 0"/>
      <geometry>
        <mesh filename="package://denso_robot_descriptions/cobotta_description/base_link.dae" scale="1 1 1"/>
      </geometry>
    </visual>
    <collision>
      <origin rpy="0 0 0" xyz="0 0 0"/>
      <geometry>
        <mesh filename="package://denso_robot_descriptions/cobotta_description/base_link.dae" scale="1 1 1"/>
      </geometry>
    </collision>
    <inertial>
      <mass value="1.4"/>
      <origin rpy="0.000000 0.000000 0.000000" xyz="-0.021310 0.000002 0.044011"/>
      <inertia ixx="0.00266" ixy="0.0" ixz="0.0" iyy="0.00266" iyz="0.0" izz="0.00448"/>
    </inertial>
  </link>
  <link name="J1">
    <visual>
      <origin rpy="0 0 0" xyz="0 0 0"/>
      <geometry>
        <mesh filename="package://denso_robot_descriptions/cobotta_description/J1.dae" scale="1 1 1"/>
      </geometry>
    </visual>
    <collision>
      <origin rpy="0 0 0" xyz="0 0 0"/>
      <geometry>
        <mesh filename="package://denso_robot_descriptions/cobotta_description/J1.dae" scale="1 1 1"/>
      </geometry>
    </collision>
    <inertial>
      <mass value="1.29"/>
      <origin rpy="0.000000 0.000000 0.000000" xyz="0.000000 0.000000 0.15"/>
      <inertia ixx="0.002236" ixy="0.0" ixz="0.0" iyy="0.002236" iyz="0.0" izz="0.002322"/>
    </inertial>
  </link>
  <joint name="joint_1" type="revolute">
    <parent link="base_link"/>
    <child link="J1"/>
    <origin rpy="0.000000 0.000000 0.000000" xyz="0.000000 0.000000 0.000000"/>
    <axis xyz="-0.000000 -0.000000 1.000000"/>
    <limit effort="10" lower="-2.617994" upper="2.617994" velocity="0.40317105721069"/>
    <dynamics damping="0.001" friction="0.61"/>
  </joint>
  <transmission name="trans_1">
    <type>transmission_interface/SimpleTransmission</type>
    <joint name="joint_1">
      <hardwareInterface>hardware_interface/PositionJointInterface</hardwareInterface>
    </joint>
    <actuator name="motor_1">
      <hardwareInterface>hardware_interface/PositionJointInterface</hardwareInterface>
      <mechanicalReduction>1</mechanicalReduction>
    </actuator>
  </transmission>
  <link name="J2">
    <visual>
      <origin rpy="0 0 0" xyz="0 0 0"/>
      <geometry>
        <mesh filename="package://denso_robot_descriptions/cobotta_description/J2.dae" scale="1 1 1"/>
      </geometry>
    </visual>
    <collision>
      <origin rpy="0 0 0" xyz="0 0 0"/>
      <geometry>
        <mesh filename="package://denso_robot_descriptions/cobotta_description/J2.dae" scale="1 1 1"/>
      </geometry>
    </collision>
    <inertial>
      <mass value="0.39"/>
      <origin rpy="0.000000 0.000000 0.000000" xyz="-0.020000 0.100000 0.070000"/>
      <inertia ixx="0.00055575" ixy="0.0" ixz="0.0" iyy="0.00055575" iyz="0.0" izz="0.0001755"/>
    </inertial>
  </link>
  <joint name="joint_2" type="revolute">
    <parent link="J1"/>
    <child link="J2"/>
    <origin rpy="0.000000 0.000000 0.000000" xyz="0.000000 0.000000 0.180000"/>
    <axis xyz="-0.000000 1.000000 -0.000000"/>
    <limit effort="10" lower="-1.047198" upper="1.745329" velocity="0.392175482923126"/>
    <dynamics damping="0.001" friction="0.61"/>
  </joint>
  <transmission name="trans_2">
    <type>transmission_interface/SimpleTransmission</type>
    <joint name="joint_2">
      <hardwareInterface>hardware_interface/PositionJointInterface</hardwareInterface>
    </joint>
    <actuator name="motor_2">
      <hardwareInterface>hardware_interface/PositionJointInterface</hardwareInterface>
      <mechanicalReduction>1</mechanicalReduction>
    </actuator>
  </transmission>
  <link name="J3">
    <visual>
      <origin rpy="0 0 0" xyz="0 0 0"/>
      <geometry>
        <mesh filename="package://denso_robot_descriptions/cobotta_description/J3.dae" scale="1 1 1"/>
      </geometry>
    </visual>
    <collision>
      <origin rpy="0 0 0" xyz="0 0 0"/>
      <geometry>
        <mesh filename="package://denso_robot_descriptions/cobotta_description/J3.dae" scale="1 1 1"/>
      </geometry>
    </collision>
    <inertial>
      <mass value="0.35"/>
      <origin rpy="0.000000 0.000000 0.000000" xyz="-0.01000 0.020000 0.030000"/>
      <inertia ixx="0.000431666666667" ixy="0.0" ixz="0.0" iyy="0.000431666666667" iyz="0.0" izz="0.0001575"/>
    </inertial>
  </link>
  <joint name="joint_3" type="revolute">
    <parent link="J2"/>
    <child link="J3"/>
    <origin rpy="0.000000 0.000000 0.000000" xyz="0.000000 0.000000 0.165000"/>
    <axis xyz="-0.000000 1.000000 -0.000000"/>
    <limit effort="10" lower="0.3141593" upper="2.443461" velocity="0.725707902979242"/>
    <dynamics damping="0.001" friction="0.61"/>
  </joint>
  <transmission name="trans_3">
    <type>transmission_interface/SimpleTransmission</type>
    <joint name="joint_3">
      <hardwareInterface>hardware_interface/PositionJointInterface</hardwareInterface>
    </joint>
    <actuator name="motor_3">
      <hardwareInterface>hardware_interface/PositionJointInterface</hardwareInterface>
      <mechanicalReduction>1</mechanicalReduction>
    </actuator>
  </transmission>
  <link name="J4">
    <visual>
      <origin rpy="0 0 0" xyz="0 0 0"/>
      <geometry>
        <mesh filename="package://denso_robot_descriptions/cobotta_description/J4.dae" scale="1 1 1"/>
      </geometry>
    </visual>
    <collision>
      <origin rpy="0 0 0" xyz="0 0 0"/>
      <geometry>
        <mesh filename="package://denso_robot_descriptions/cobotta_description/J4.dae" scale="1 1 1"/>
      </geometry>
    </collision>
    <inertial>
      <mass value="0.35"/>
      <origin rpy="0.000000 0.000000 0.000000" xyz="0.0000 0.000000 0.055000"/>
      <inertia ixx="0.000431666666667" ixy="0.0" ixz="0.0" iyy="0.000431666666667" iyz="0.0" izz="0.0001575"/>
    </inertial>
  </link>
  <joint name="joint_4" type="revolute">
    <parent link="J3"/>
    <child link="J4"/>
    <origin rpy="0.000000 0.000000 0.000000" xyz="-0.012000 0.020000 0.088000"/>
    <axis xyz="-0.000000 -0.000000 1.000000"/>
    <limit effort="10" lower="-2.96706" upper="2.96706" velocity="0.739146938219599"/>
    <dynamics damping="0.001" friction="0.61"/>
  </joint>
  <transmission name="trans_4">
    <type>transmission_interface/SimpleTransmission</type>
    <joint name="joint_4">
      <hardwareInterface>hardware_interface/PositionJointInterface</hardwareInterface>
    </joint>
    <actuator name="motor_4">
      <hardwareInterface>hardware_interface/PositionJointInterface</hardwareInterface>
      <mechanicalReduction>1</mechanicalReduction>
    </actuator>
  </transmission>
  <link name="J5">
    <visual>
      <origin rpy="0 0 0" xyz="0 0 0"/>
      <geometry>
        <mesh filename="package://denso_robot_descriptions/cobotta_description/J5.dae" scale="1 1 1"/>
      </geometry>
    </visual>
    <collision>
      <origin rpy="0 0 0" xyz="0 0 0"/>
      <geometry>
        <mesh filename="package://denso_robot_descriptions/cobotta_description/J5.dae" scale="1 1 1"/>
      </geometry>
    </collision>
    <inertial>
      <mass value="0.19"/>
      <origin rpy="0.000000 0.000000 0.000000" xyz="0.000000 -0.040000 0.015000"/>
      <inertia ixx="9.975e-05" ixy="0.0" ixz="0.0" iyy="9.975e-05" iyz="0.0" izz="8.55e-05"/>
    </inertial>
  </link>
  <joint name="joint_5" type="revolute">
    <parent link="J4"/>
    <child link="J5"/>
    <origin rpy="0.000000 0.000000 0.000000" xyz="0.000000 -0.020000 0.089500"/>
    <axis xyz="-0.000000 1.000000 -0.000000"/>
    <limit effort="10" lower="-1.658063" upper="2.356194" velocity="0.739146938219599"/>
    <dynamics damping="0.001" friction="0.61"/>
  </joint>
  <transmission name="trans_5">
    <type>transmission_interface/SimpleTransmission</type>
    <joint name="joint_5">
      <hardwareInterface>hardware_interface/PositionJointInterface</hardwareInterface>
    </joint>
    <actuator name="motor_5">
      <hardwareInterface>hardware_interface/PositionJointInterface</hardwareInterface>
      <mechanicalReduction>1</mechanicalReduction>
    </actuator>
  </transmission>
  <link name="J6">
    <visual>
      <origin rpy="0 0 0" xyz="0 0 0"/>
      <geometry>
        <mesh filename="package://denso_robot_descriptions/cobotta_description/J6.dae" scale="1 1 1"/>
      </geometry>
    </visual>
    <collision>
      <origin rpy="0 0 0" xyz="0 0 0"/>
      <geometry>
        <mesh filename="package://denso_robot_descriptions/cobotta_description/J6.dae" scale="1 1 1"/>
      </geometry>
    </collision>
    <inertial>
      <mass value="0.03"/>
      <origin rpy="0.000000 0.000000 0.000000" xyz="0.000000 0.000000 0.000000"/>
      <inertia ixx="7e-06" ixy="0.0" ixz="0.0" iyy="7e-06" iyz="0.0" izz="1.35e-05"/>
    </inertial>
  </link>
  <joint name="joint_6" type="revolute">
    <parent link="J5"/>
    <child link="J6"/>
    <origin rpy="0.000000 0.000000 0.000000" xyz="0.000000 -0.044500 0.042000"/>
    <axis xyz="-0.000000 -0.000000 1.000000"/>
    <limit effort="10" lower="-2.96706" upper="2.96706" velocity="1.1093312725676"/>
    <dynamics damping="0.001" friction="0.61"/>
  </joint>
  <transmission name="trans_6">
    <type>transmission_interface/SimpleTransmission</type>
    <joint name="joint_6">
      <hardwareInterface>hardware_interface/PositionJointInterface</hardwareInterface>
    </joint>
    <actuator name="motor_6">
      <hardwareInterface>hardware_interface/PositionJointInterface</hardwareInterface>
      <mechanicalReduction>1</mechanicalReduction>
    </actuator>
  </transmission>
  <link name="gripper_base">
    <visual>
      <origin rpy="0 0 0" xyz="0.000000 0.000000 0.000000"/>
      <geometry>
        <mesh filename="package://denso_robot_descriptions/cobotta_description/gripper_base.dae" scale="1 1 1"/>
      </geometry>
    </visual>
    <collision>
      <origin rpy="0 0 0" xyz="0 0 0"/>
      <geometry>
        <mesh filename="package://denso_robot_descriptions/cobotta_description/gripper_base.dae" scale="1 1 1"/>
      </geometry>
    </collision>
    <inertial>
      <mass value="1"/>
      <origin rpy="0.000000 0.000000 0.000000" xyz="0.000000 0.000000 0.000000"/>
      <inertia ixx="1" ixy="0" ixz="0" iyy="1" iyz="0" izz="1"/>
    </inertial>
  </link>
  <joint name="joint_gripper_base" type="fixed">
    <parent link="J6"/>
    <child link="gripper_base"/>
    <origin rpy="0.000000 0.000000 0.000000" xyz="0.000000 0.000000 0.0000000"/>
  </joint>
  <link name="left_finger">
    <visual>
      <origin rpy="0.000000 0.000000 0.000000" xyz="0.000000 0.000000 -0.060000"/>
      <geometry>
        <mesh filename="package://denso_robot_descriptions/cobotta_description/left_finger.dae" scale="1 1 1"/>
      </geometry>
    </visual>
    <collision>
      <origin rpy="0 0 0" xyz="0.000000 0.000000 -0.060000"/>
      <geometry>
        <mesh filename="package://denso_robot_descriptions/cobotta_description/left_finger.dae" scale="1 1 1"/>
      </geometry>
    </collision>
    <inertial>
      <mass value="1"/>
      <origin rpy="0.000000 0.000000 0.000000" xyz="0.000000 0.000000 0.000000"/>
      <inertia ixx="1" ixy="0" ixz="0" iyy="1" iyz="0" izz="1"/>
    </inertial>
  </link>
  <joint name="joint_gripper" type="prismatic">
    <parent link="gripper_base"/>
    <child link="left_finger"/>
    <origin rpy="0.000000 0.000000 0.000000" xyz="0.000000 0.000000 0.06000"/>
    <axis xyz="-0.000000 1.000000 -0.000000"/>
    <limit effort="20" lower="0.000000" upper="0.015000" velocity="0.040000"/>
    <dynamics damping="0" friction="0"/>
  </joint>
  <transmission name="trans_gripper">
    <type>transmission_interface/SimpleTransmission</type>
    <joint name="joint_gripper">
      <hardwareInterface>hardware_interface/PositionJointInterface</hardwareInterface>
    </joint>
    <actuator name="motor_gripper">
      <hardwareInterface>hardware_interface/PositionJointInterface</hardwareInterface>
      <mechanicalReduction>1</mechanicalReduction>
    </actuator>
  </transmission>
  <link name="right_finger">
    <visual>
      <origin rpy="0.000000 0.000000 0.000000" xyz="0.000000 0.000000 -0.060000"/>
      <geometry>
        <mesh filename="package://denso_robot_descriptions/cobotta_description/right_finger.dae" scale="1 1 1"/>
      </geometry>
    </visual>
    <collision>
      <origin rpy="0 0 0" xyz="0.000000 0.000000 -0.060000"/>
      <geometry>
        <mesh filename="package://denso_robot_descriptions/cobotta_description/right_finger.dae" scale="1 1 1"/>
      </geometry>
    </collision>
    <inertial>
      <mass value="1"/>
      <origin rpy="0.000000 0.000000 0.000000" xyz="0.000000 0.000000 0.000000"/>
      <inertia ixx="1" ixy="0" ixz="0" iyy="1" iyz="0" izz="1"/>
    </inertial>
  </link>
  <joint name="joint_gripper_mimic" type="prismatic">
    <parent link="gripper_base"/>
    <child link="right_finger"/>
    <mimic joint="joint_gripper" multiplier="-1.000000" offset="0.000000"/>
    <origin rpy="0.000000 0.000000 0.000000" xyz="0.000000 0.000000 0.060000"/>
    <axis xyz="-0.000000 1.000000 -0.000000"/>
    <limit effort="20" lower="-0.015000" upper="0.000000" velocity="0.040000"/>
    <dynamics damping="0" friction="0"/>
  </joint>
</robot>

